Workbook

Sheet vgsales
A1: Rank | B1: Name | C1: Platform | D1: Year | E1: Genre | F1: Publisher | G1: NA_Sales | H1: EU_Sales | I1: JP_Sales | J1: Other_Sales | K1: Global_Sales | L1: Sales Category | M1: Platform Code | N1: Game Summary
A2: 1 | B2: Wii Sports | C2: Wii | D2: 2006 | E2: Sports | F2: Nintendo | G2: 41.49 | H2: 29.02 | I2: 3.77 | J2: 8.46 | K2: 82.74 | L2: =IF(K2 > 10, "Blockbuster", IF(K2 > 1, "Standard", "Niche")) -> Blockbuster | M2: =LEFT(C2, 3) -> Wii | N2: =CONCATENATE(B2, " ", "(", C2, ")") -> Wii Sports (Wii)
A3: 2 | B3: Super Mario Bros. | C3: NES | D3: 1985 | E3: Platform | F3: Nintendo | G3: 29.08 | H3: 3.58 | I3: 6.81 | J3: 0.77 | K3: 40.24 | L3: =IF(K3 > 10, "Blockbuster", IF(K3 > 1, "Standard", "Niche")) -> Blockbuster | M3: =LEFT(C3, 3) -> NES | N3: =CONCATENATE(B3, " ", "(", C3, ")") -> Super Mario Bros. (NES)
A4: 3 | B4: Mario Kart Wii | C4: Wii | D4: 2008 | E4: Racing | F4: Nintendo | G4: 15.85 | H4: 12.88 | I4: 3.79 | J4: 3.31 | K4: 35.82 | L4: =IF(K4 > 10, "Blockbuster", IF(K4 > 1, "Standard", "Niche")) -> Blockbuster | M4: =LEFT(C4, 3) -> Wii | N4: =CONCATENATE(B4, " ", "(", C4, ")") -> Mario Kart Wii (Wii)
A5: 4 | B5: Wii Sports Resort | C5: Wii | D5: 2009 | E5: Sports | F5: Nintendo | G5: 15.75 | H5: 11.01 | I5: 3.28 | J5: 2.96 | K5: 33 | L5: =IF(K5 > 10, "Blockbuster", IF(K5 > 1, "Standard", "Niche")) -> Blockbuster | M5: =LEFT(C5, 3) -> Wii | N5: =CONCATENATE(B5, " ", "(", C5, ")") -> Wii Sports Resort (Wii)
A6: 5 | B6: Pokemon Red/Pokemon Blue | C6: GB | D6: 1996 | E6: Role-Playing | F6: Nintendo | G6: 11.27 | H6: 8.89 | I6: 10.22 | J6: 1 | K6: 31.37 | L6: =IF(K6 > 10, "Blockbuster", IF(K6 > 1, "Standard", "Niche")) -> Blockbuster | M6: =LEFT(C6, 3) -> GB | N6: =CONCATENATE(B6, " ", "(", C6, ")") -> Pokemon Red/Pokemon Blue (GB)
A7: 6 | B7: Tetris | C7: GB | D7: 1989 | E7: Puzzle | F7: Nintendo | G7: 23.2 | H7: 2.26 | I7: 4.22 | J7: 0.58 | K7: 30.26 | L7: =IF(K7 > 10, "Blockbuster", IF(K7 > 1, "Standard", "Niche")) -> Blockbuster | M7: =LEFT(C7, 3) -> GB | N7: =CONCATENATE(B7, " ", "(", C7, ")") -> Tetris (GB)
A8: 7 | B8: New Super Mario Bros. | C8: DS | D8: 2006 | E8: Platform | F8: Nintendo | G8: 11.38 | H8: 9.23 | I8: 6.5 | J8: 2.9 | K8: 30.01 | L8: =IF(K8 > 10, "Blockbuster", IF(K8 > 1, "Standard", "Niche")) -> Blockbuster | M8: =LEFT(C8, 3) -> DS | N8: =CONCATENATE(B8, " ", "(", C8, ")") -> New Super Mario Bros. (DS)
A9: 8 | B9: Wii Play | C9: Wii | D9: 2006 | E9: Misc | F9: Nintendo | G9: 14.03 | H9: 9.2 | I9: 2.93 | J9: 2.85 | K9: 29.02 | L9: =IF(K9 > 10, "Blockbuster", IF(K9 > 1, "Standard", "Niche")) -> Blockbuster | M9: =LEFT(C9, 3) -> Wii | N9: =CONCATENATE(B9, " ", "(", C9, ")") -> Wii Play (Wii)
A10: 9 | B10: New Super Mario Bros. Wii | C10: Wii | D10: 2009 | E10: Platform | F10: Nintendo | G10: 14.59 | H10: 7.06 | I10: 4.7 | J10: 2.26 | K10: 28.62 | L10: =IF(K10 > 10, "Blockbuster", IF(K10 > 1, "Standard", "Niche")) -> Blockbuster | M10: =LEFT(C10, 3) -> Wii | N10: =CONCATENATE(B10, " ", "(", C10, ")") -> New Super Mario Bros. Wii (Wii)
A11: 10 | B11: Duck Hunt | C11: NES | D11: 1984 | E11: Shooter | F11: Nintendo | G11: 26.93 | H11: 0.63 | I11: 0.28 | J11: 0.47 | K11: 28.31 | L11: =IF(K11 > 10, "Blockbuster", IF(K11 > 1, "Standard", "Niche")) -> Blockbuster | M11: =LEFT(C11, 3) -> NES | N11: =CONCATENATE(B11, " ", "(", C11, ")") -> Duck Hunt (NES)
A12: 11 | B12: Nintendogs | C12: DS | D12: 2005 | E12: Simulation | F12: Nintendo | G12: 9.07 | H12: 11 | I12: 1.93 | J12: 2.75 | K12: 24.76 | L12: =IF(K12 > 10, "Blockbuster", IF(K12 > 1, "Standard", "Niche")) -> Blockbuster | M12: =LEFT(C12, 3) -> DS | N12: =CONCATENATE(B12, " ", "(", C12, ")") -> Nintendogs (DS)
A13: 12 | B13: Mario Kart DS | C13: DS | D13: 2005 | E13: Racing | F13: Nintendo | G13: 9.81 | H13: 7.57 | I13: 4.13 | J13: 1.92 | K13: 23.42 | L13: =IF(K13 > 10, "Blockbuster", IF(K13 > 1, "Standard", "Niche")) -> Blockbuster | M13: =LEFT(C13, 3) -> DS | N13: =CONCATENATE(B13, " ", "(", C13, ")") -> Mario Kart DS (DS)
... A90: 89 | B90: PokÃ©mon Platinum Version | C90: DS | D90: 2008 | E90: Role-Playing | F90: Nintendo | G90: 2.82 | H90: 1.78 | I90: 2.69 | J90: 0.55 | K90: 7.84 | L90: =IF(K90 > 10, "Blockbuster", IF(K90 > 1, "Standard", "Niche")) -> Standard | M90: =LEFT(C90, 3) -> DS | N90: =CONCATENATE(B90, " ", "(", C90, ")") -> PokÃ©mon Platinum Version (DS)
A91: 90 | B91: Pac-Man | C91: 2600 | D91: 1982 | E91: Puzzle | F91: Atari | G91: 7.28 | H91: 0.45 | I91: 0 | J91: 0.08 | K91: 7.81 | L91: =IF(K91 > 10, "Blockbuster", IF(K91 > 1, "Standard", "Niche")) -> Standard | M91: =LEFT(C91, 3) -> 260 | N91: =CONCATENATE(B91, " ", "(", C91, ")") -> Pac-Man (2600)
A92: 91 | B92: Grand Theft Auto: Liberty City Stories | C92: PSP | D92: 2005 | E92: Action | F92: Take-Two Interactive | G92: 2.9 | H92: 2.83 | I92: 0.24 | J92: 1.75 | K92: 7.72 | L92: =IF(K92 > 10, "Blockbuster", IF(K92 > 1, "Standard", "Niche")) -> Standard | M92: =LEFT(C92, 3) -> PSP | N92: =CONCATENATE(B92, " ", "(", C92, ")") -> Grand Theft Auto: Liberty City Stories (PSP)
A93: 92 | B93: Super Mario Galaxy 2 | C93: Wii | D93: 2010 | E93: Platform | F93: Nintendo | G93: 3.66 | H93: 2.42 | I93: 0.98 | J93: 0.64 | K93: 7.69 | L93: =IF(K93 > 10, "Blockbuster", IF(K93 > 1, "Standard", "Niche")) -> Standard | M93: =LEFT(C93, 3) -> Wii | N93: =CONCATENATE(B93, " ", "(", C93, ")") -> Super Mario Galaxy 2 (Wii)
A94: 93 | B94: Star Wars Battlefront (2015) | C94: PS4 | D94: 2015 | E94: Shooter | F94: Electronic Arts | G94: 2.93 | H94: 3.29 | I94: 0.22 | J94: 1.23 | K94: 7.67 | L94: =IF(K94 > 10, "Blockbuster", IF(K94 > 1, "Standard", "Niche")) -> Standard | M94: =LEFT(C94, 3) -> PS4 | N94: =CONCATENATE(B94, " ", "(", C94, ")") -> Star Wars Battlefront (2015) (PS4)
A95: 94 | B95: Call of Duty: Advanced Warfare | C95: PS4 | D95: 2014 | E95: Shooter | F95: Activision | G95: 2.8 | H95: 3.3 | I95: 0.14 | J95: 1.37 | K95: 7.6 | L95: =IF(K95 > 10, "Blockbuster", IF(K95 > 1, "Standard", "Niche")) -> Standard | M95: =LEFT(C95, 3) -> PS4 | N95: =CONCATENATE(B95, " ", "(", C95, ")") -> Call of Duty: Advanced Warfare (PS4)
A96: 95 | B96: The Legend of Zelda: Ocarina of Time | C96: N64 | D96: 1998 | E96: Action | F96: Nintendo | G96: 4.1 | H96: 1.89 | I96: 1.45 | J96: 0.16 | K96: 7.6 | L96: =IF(K96 > 10, "Blockbuster", IF(K96 > 1, "Standard", "Niche")) -> Standard | M96: =LEFT(C96, 3) -> N64 | N96: =CONCATENATE(B96, " ", "(", C96, ")") -> The Legend of Zelda: Ocarina of Time (N64)
A97: 96 | B97: Crash Bandicoot 2: Cortex Strikes Back | C97: PS | D97: 1997 | E97: Platform | F97: Sony Computer Entertainment | G97: 3.78 | H97: 2.17 | I97: 1.31 | J97: 0.31 | K97: 7.58 | L97: =IF(K97 > 10, "Blockbuster", IF(K97 > 1, "Standard", "Niche")) -> Standard | M97: =LEFT(C97, 3) -> PS | N97: =CONCATENATE(B97, " ", "(", C97, ")") -> Crash Bandicoot 2: Cortex Strikes Back (PS)
A98: 97 | B98: Super Mario Bros. 2 | C98: NES | D98: 1988 | E98: Platform | F98: Nintendo | G98: 5.39 | H98: 1.18 | I98: 0.7 | J98: 0.19 | K98: 7.46 | L98: =IF(K98 > 10, "Blockbuster", IF(K98 > 1, "Standard", "Niche")) -> Standard | M98: =LEFT(C98, 3) -> NES | N98: =CONCATENATE(B98, " ", "(", C98, ")") -> Super Mario Bros. 2 (NES)
A99: 98 | B99: Super Smash Bros. for Wii U and 3DS | C99: 3DS | D99: 2014 | E99: Fighting | F99: Nintendo | G99: 3.24 | H99: 1.35 | I99: 2.42 | J99: 0.43 | K99: 7.45 | L99: =IF(K99 > 10, "Blockbuster", IF(K99 > 1, "Standard", "Niche")) -> Standard | M99: =LEFT(C99, 3) -> 3DS | N99: =CONCATENATE(B99, " ", "(", C99, ")") -> Super Smash Bros. for Wii U and 3DS (3DS)
A100: 99 | B100: Call of Duty: World at War | C100: X360 | D100: 2008 | E100: Shooter | F100: Activision | G100: 4.79 | H100: 1.9 | I100: 0 | J100: 0.69 | K100: 7.37 | L100: =IF(K100 > 10, "Blockbuster", IF(K100 > 1, "Standard", "Niche")) -> Standard | M100: =LEFT(C100, 3) -> X36 | N100: =CONCATENATE(B100, " ", "(", C100, ")") -> Call of Duty: World at War (X360)
A101: 100 | B101: Battlefield 3 | C101: X360 | D101: 2011 | E101: Shooter | F101: Electronic Arts | G101: 4.46 | H101: 2.13 | I101: 0.06 | J101: 0.69 | K101: 7.34 | L101: =IF(K101 > 10, "Blockbuster", IF(K101 > 1, "Standard", "Niche")) -> Standard | M101: =LEFT(C101, 3) -> X36 | N101: =CONCATENATE(B101, " ", "(", C101, ")") -> Battlefield 3 (X360)
A102: 101 | B102: The Legend of Zelda: Twilight Princess | C102: Wii | D102: 2006 | E102: Action | F102: Nintendo | G102: 3.83 | H102: 2.19 | I102: 0.6 | J102: 0.7 | K102: 7.31 | L102: =IF(K102 > 10, "Blockbuster", IF(K102 > 1, "Standard", "Niche")) -> Standard | M102: =LEFT(C102, 3) -> Wii | N102: =CONCATENATE(B102, " ", "(", C102, ")") -> The Legend of Zelda: Twilight Princess (Wii)
A103: 102 | B103: Call of Duty: Black Ops 3 | C103: XOne | D103: 2015 | E103: Shooter | F103: Activision | G103: 4.52 | H103: 2.09 | I103: 0.01 | J103: 0.67 | K103: 7.3 | L103: =IF(K103 > 10, "Blockbuster", IF(K103 > 1, "Standard", "Niche")) -> Standard | M103: =LEFT(C103, 3) -> XOn | N103: =CONCATENATE(B103, " ", "(", C103, ")") -> Call of Duty: Black Ops 3 (XOne)
... A180: 179 | B180: Tomb Raider II | C180: PS | D180: 1997 | E180: Action | F180: Eidos Interactive | G180: 2.3 | H180: 2.46 | I180: 0.2 | J180: 0.28 | K180: 5.24 | L180: =IF(K180 > 10, "Blockbuster", IF(K180 > 1, "Standard", "Niche")) -> Standard | M180: =LEFT(C180, 3) -> PS | N180: =CONCATENATE(B180, " ", "(", C180, ")") -> Tomb Raider II (PS)
A181: 180 | B181: Madden NFL 2004 | C181: PS2 | D181: N/A | E181: Sports | F181: Electronic Arts | G181: 4.26 | H181: 0.26 | I181: 0.01 | J181: 0.71 | K181: 5.23 | L181: =IF(K181 > 10, "Blockbuster", IF(K181 > 1, "Standard", "Niche")) -> Standard | M181: =LEFT(C181, 3) -> PS2 | N181: =CONCATENATE(B181, " ", "(", C181, ")") -> Madden NFL 2004 (PS2)
A182: 181 | B182: Dragon Quest VIII: Journey of the Cursed King | C182: PS2 | D182: 2004 | E182: Role-Playing | F182: Square Enix | G182: 0.65 | H182: 0.75 | I182: 3.61 | J182: 0.2 | K182: 5.21 | L182: =IF(K182 > 10, "Blockbuster", IF(K182 > 1, "Standard", "Niche")) -> Standard | M182: =LEFT(C182, 3) -> PS2 | N182: =CONCATENATE(B182, " ", "(", C182, ")") -> Dragon Quest VIII: Journey of the Cursed King (PS2)
A183: 182 | B183: Diablo III | C183: PC | D183: 2012 | E183: Role-Playing | F183: Activision | G183: 2.43 | H183: 2.15 | I183: 0 | J183: 0.62 | K183: 5.2 | L183: =IF(K183 > 10, "Blockbuster", IF(K183 > 1, "Standard", "Niche")) -> Standard | M183: =LEFT(C183, 3) -> PC | N183: =CONCATENATE(B183, " ", "(", C183, ")") -> Diablo III (PC)
A184: 183 | B184: Super Mario Bros. 3 | C184: GBA | D184: 2003 | E184: Platform | F184: Nintendo | G184: 2.93 | H184: 1.25 | I184: 0.83 | J184: 0.2 | K184: 5.2 | L184: =IF(K184 > 10, "Blockbuster", IF(K184 > 1, "Standard", "Niche")) -> Standard | M184: =LEFT(C184, 3) -> GBA | N184: =CONCATENATE(B184, " ", "(", C184, ")") -> Super Mario Bros. 3 (GBA)
A185: 184 | B185: New Super Mario Bros. U | C185: WiiU | D185: 2012 | E185: Platform | F185: Nintendo | G185: 2.32 | H185: 1.3 | I185: 1.27 | J185: 0.31 | K185: 5.19 | L185: =IF(K185 > 10, "Blockbuster", IF(K185 > 1, "Standard", "Niche")) -> Standard | M185: =LEFT(C185, 3) -> Wii | N185: =CONCATENATE(B185, " ", "(", C185, ")") -> New Super Mario Bros. U (WiiU)
A186: 185 | B186: Super Mario Land 3: Wario Land | C186: GB | D186: 1994 | E186: Platform | F186: Nintendo | G186: 2.49 | H186: 0.98 | I186: 1.57 | J186: 0.15 | K186: 5.19 | L186: =IF(K186 > 10, "Blockbuster", IF(K186 > 1, "Standard", "Niche")) -> Standard | M186: =LEFT(C186, 3) -> GB | N186: =CONCATENATE(B186, " ", "(", C186, ")") -> Super Mario Land 3: Wario Land (GB)
A187: 186 | B187: FIFA Soccer 13 | C187: X360 | D187: 2012 | E187: Action | F187: Electronic Arts | G187: 1.08 | H187: 3.48 | I187: 0.03 | J187: 0.58 | K187: 5.18 | L187: =IF(K187 > 10, "Blockbuster", IF(K187 > 1, "Standard", "Niche")) -> Standard | M187: =LEFT(C187, 3) -> X36 | N187: =CONCATENATE(B187, " ", "(", C187, ")") -> FIFA Soccer 13 (X360)
A188: 187 | B188: The Legend of Zelda: Phantom Hourglass | C188: DS | D188: 2007 | E188: Action | F188: Nintendo | G188: 1.9 | H188: 1.83 | I188: 0.95 | J188: 0.49 | K188: 5.17 | L188: =IF(K188 > 10, "Blockbuster", IF(K188 > 1, "Standard", "Niche")) -> Standard | M188: =LEFT(C188, 3) -> DS | N188: =CONCATENATE(B188, " ", "(", C188, ")") -> The Legend of Zelda: Phantom Hourglass (DS)
A189: 188 | B189: Donkey Kong Country 2: Diddy's Kong Quest | C189: SNES | D189: 1995 | E189: Platform | F189: Nintendo | G189: 2.1 | H189: 0.74 | I189: 2.2 | J189: 0.11 | K189: 5.15 | L189: =IF(K189 > 10, "Blockbuster", IF(K189 > 1, "Standard", "Niche")) -> Standard | M189: =LEFT(C189, 3) -> SNE | N189: =CONCATENATE(B189, " ", "(", C189, ")") -> Donkey Kong Country 2: Diddy's Kong Quest (SNES)
A190: 189 | B190: Tomodachi Life | C190: 3DS | D190: 2013 | E190: Simulation | F190: Nintendo | G190: 0.96 | H190: 2.02 | I190: 1.89 | J190: 0.28 | K190: 5.15 | L190: =IF(K190 > 10, "Blockbuster", IF(K190 > 1, "Standard", "Niche")) -> Standard | M190: =LEFT(C190, 3) -> 3DS | N190: =CONCATENATE(B190, " ", "(", C190, ")") -> Tomodachi Life (3DS)
A191: 190 | B191: Mario & Sonic at the Olympic Games | C191: DS | D191: 2008 | E191: Sports | F191: Sega | G191: 1.64 | H191: 2.48 | I191: 0.44 | J191: 0.58 | K191: 5.14 | L191: =IF(K191 > 10, "Blockbuster", IF(K191 > 1, "Standard", "Niche")) -> Standard | M191: =LEFT(C191, 3) -> DS | N191: =CONCATENATE(B191, " ", "(", C191, ")") -> Mario & Sonic at the Olympic Games (DS)
A192: 191 | B192: Medal of Honor: Rising Sun | C192: PS2 | D192: 2003 | E192: Shooter | F192: Electronic Arts | G192: 1.98 | H192: 2.23 | I192: 0.13 | J192: 0.8 | K192: 5.13 | L192: =IF(K192 > 10, "Blockbuster", IF(K192 > 1, "Standard", "Niche")) -> Standard | M192: =LEFT(C192, 3) -> PS2 | N192: =CONCATENATE(B192, " ", "(", C192, ")") -> Medal of Honor: Rising Sun (PS2)
...

Sheet Lookup Practice
A1: Game | B1: Global Sales (VLOOKUP) | C1: Global Sales (XLOOKUP)
A2: Wii Sports | B2: =IFERROR(VLOOKUP(TRIM(A2),vgsales!B:K,10,FALSE),"Not Found") -> 82.74 | C2: =IFERROR(_xlfn.XLOOKUP(TRIM(A2),vgsales!B:B,vgsales!K:K),"Not Found") -> 82.74
A3: Super Mario Bros. | B3: =IFERROR(VLOOKUP(TRIM(A3),vgsales!B:K,10,FALSE),"Not Found") -> 40.24 | C3: =IFERROR(_xlfn.XLOOKUP(TRIM(A3),vgsales!B:B,vgsales!K:K),"Not Found") -> 40.24
A4: Mario Kart Wii | B4: =IFERROR(VLOOKUP(TRIM(A4),vgsales!B:K,10,FALSE),"Not Found") -> 35.82 | C4: =IFERROR(_xlfn.XLOOKUP(TRIM(A4),vgsales!B:B,vgsales!K:K),"Not Found") -> 35.82
A5: Wii Sports Resort | B5: =IFERROR(VLOOKUP(TRIM(A5),vgsales!B:K,10,FALSE),"Not Found") -> 33 | C5: =IFERROR(_xlfn.XLOOKUP(TRIM(A5),vgsales!B:B,vgsales!K:K),"Not Found") -> 33
A6: Fake Game 2024 | B6: =IFERROR(VLOOKUP(TRIM(A6),vgsales!B:K,10,FALSE),"Not Found") -> Not Found | C6: =IFERROR(_xlfn.XLOOKUP(TRIM(A6),vgsales!B:B,vgsales!K:K),"Not Found") -> Not Found
A7: Wii Sports | B7: =IFERROR(VLOOKUP(TRIM(A7),vgsales!B:K,10,FALSE),"Not Found") -> 82.74 | C7: =IFERROR(_xlfn.XLOOKUP(TRIM(A7),vgsales!B:B,vgsales!K:K),"Not Found") -> 82.74

Sheet Summary
A1: GENRE | B1: GAME COUNT | C1: Global Sales (M) | D1: Average Sales Per Game (M)
A2: Action | B2: =COUNTIF(vgsales!E:E, A2) -> 3316 | C2: =SUMIF(vgsales!E:E, A2, vgsales!K:K) -> 1751.18 | D2: =ROUND(AVERAGEIF(vgsales!E:E, A2, vgsales!K:K),2) -> 0.53
A3: Sports | B3: =COUNTIF(vgsales!E:E, A3) -> 2346 | C3: =SUMIF(vgsales!E:E, A3, vgsales!K:K) -> 1330.93 | D3: =ROUND(AVERAGEIF(vgsales!E:E, A3, vgsales!K:K),2) -> 0.57
A4: Shooter | B4: =COUNTIF(vgsales!E:E, A4) -> 1310 | C4: =SUMIF(vgsales!E:E, A4, vgsales!K:K) -> 1037.37 | D4: =ROUND(AVERAGEIF(vgsales!E:E, A4, vgsales!K:K),2) -> 0.79
A5: Role-Playing | B5: =COUNTIF(vgsales!E:E, A5) -> 1488 | C5: =SUMIF(vgsales!E:E, A5, vgsales!K:K) -> 927.37 | D5: =ROUND(AVERAGEIF(vgsales!E:E, A5, vgsales!K:K),2) -> 0.62
A6: Racing | B6: =COUNTIF(vgsales!E:E, A6) -> 1249 | C6: =SUMIF(vgsales!E:E, A6, vgsales!K:K) -> 732.04 | D6: =ROUND(AVERAGEIF(vgsales!E:E, A6, vgsales!K:K),2) -> 0.59

Sheet Pivot Analysis
A3: Row Labels | B3: Avg Sales Per Game | C3: Sum of Global_Sales
A4: Action | B4: 0.52810012 | C4: 1751.18
A5: Sports | B5: 0.56731884 | C5: 1330.93
A6: Shooter | B6: 0.7918855 | C6: 1037.37
A7: Role-Playing | B7: 0.62323253 | C7: 927.37
A8: Platform | B8: 0.93834086 | C8: 831.37
A9: Misc | B9: 0.46576193 | C9: 809.96
A10: Racing | B10: 0.58610088 | C10: 732.04
A11: Fighting | B11: 0.529375 | C11: 448.91
A12: Simulation | B12: 0.45236448 | C12: 392.2
A13: Puzzle | B13: 0.42087629 | C13: 244.95
A14: Adventure | B14: 0.18587869 | C14: 239.04
A15: Strategy | B15: 0.25715125 | C15: 175.12
A16: Grand Total | B16: 0.53744066 | C16: 8920.44

Sheet Dashboard
G1: VIDEO GAME SALES ANALYSIS
